Workbook

Sheet CONSULTAR
C4: Código Fipe | D4: 002107-5
C5: Categoria PR | D5: =VLOOKUP(D4,BASE!A:L,11,0) -> FAIXA 03
C6: Cota PR | D6: =VLOOKUP(D4,BASE!A:L,12,0) -> COTA 02
C7: Categoria SC | D7: =VLOOKUP(D4,BASE!A:L,6,0) -> SUV grande
C8: Cota SC | D8: =VLOOKUP(D4,BASE!A:L,5,0) -> SUV GRANDE
C9: Montadora | D9: =VLOOKUP(D4,BASE!A:L,2,0) -> Toyota
C10: Modelo | D10: =VLOOKUP(D4,BASE!A:L,3,0) -> Hilux SW4 SR 4x2 2.7/ 2.7 Flex 16V Aut.
C11: Ano inicial | D11: =VLOOKUP(D4,BASE!A:L,8,0) -> 2009
C12: Ano final | D12: =VLOOKUP(D4,BASE!A:L,9,0) -> 2022

Sheet BASE
A2: ANO BASE | B2: 2026
A5: Código Fipe | B5: Montadora | C5: Modelo | D5: Tipo veículo | E5: Cota | F5: Categoria | G5: Linha | H5: Ano inicial | I5: Ano final | J5: Tempo no mercado | K5: TABELA | L5: COTA | M5: Última produção | N5: INATIVADO
A6: 008030-6 | B6: AUDI | C6: 100 2.8 V6 | D6: SEDAN | E6: NÃO COBRE | F6: NÃO COBRE | G6: 100 | H6: 1993 | I6: 1995 | J6: =1+(I6-H6) -> 3 | K6: NÃO COBRE | L6: NÃO COBRE | M6: =IF(I6=0,0,$B$2-I6) -> 31
A7: 008076-4 | B7: AUDI | C7: 100 2.8 V6 Avant | D7: SEDAN | E7: NÃO COBRE | F7: NÃO COBRE | G7: 100 | H7: 1994 | I7: 1995 | J7: =1+(I7-H7) -> 2 | K7: NÃO COBRE | L7: NÃO COBRE | M7: =IF(I7=0,0,$B$2-I7) -> 31
A8: 008031-4 | B8: AUDI | C8: 100 S-4 2.2 Avant Turbo | D8: SEDAN | E8: NÃO COBRE | F8: NÃO COBRE | G8: 100 | H8: 1994 | I8: 1995 | J8: =1+(I8-H8) -> 2 | K8: NÃO COBRE | L8: NÃO COBRE | M8: =IF(I8=0,0,$B$2-I8) -> 31
A9: 024042-7 | B9: Peugeot | C9: 106 KID 1.0 | D9: HATCH | E9: NÃO COBRE | F9: NÃO COBRE | G9: 106 | H9: 1994 | I9: 1995 | J9: =1+(I9-H9) -> 2 | K9: NÃO COBRE | L9: NÃO COBRE | M9: =IF(I9=0,0,$B$2-I9) -> 31 | N9: INATIVADO
A10: 024028-1 | B10: Peugeot | C10: 106 Passion 1.0 3p | D10: HATCH | E10: NÃO COBRE | F10: NÃO COBRE | G10: 106 | H10: 1998 | I10: 2001 | J10: =1+(I10-H10) -> 4 | K10: NÃO COBRE | L10: NÃO COBRE | M10: =IF(I10=0,0,$B$2-I10) -> 25 | N10: INATIVADO
A11: 024066-4 | B11: Peugeot | C11: 106 Passion 1.0 5p | D11: HATCH | E11: NÃO COBRE | F11: NÃO COBRE | G11: 106 | H11: 1998 | I11: 2001 | J11: =1+(I11-H11) -> 4 | K11: NÃO COBRE | L11: NÃO COBRE | M11: =IF(I11=0,0,$B$2-I11) -> 25 | N11: INATIVADO
A12: 024078-8 | B12: Peugeot | C12: 106 Quiksilver 1.0 3p | D12: HATCH | E12: NÃO COBRE | F12: NÃO COBRE | G12: 106 | H12: 2001 | I12: 2001 | J12: =1+(I12-H12) -> 1 | K12: NÃO COBRE | L12: NÃO COBRE | M12: =IF(I12=0,0,$B$2-I12) -> 25 | N12: INATIVADO
A13: 024026-5 | B13: Peugeot | C13: 106 Selection 1.0 3p | D13: HATCH | E13: NÃO COBRE | F13: NÃO COBRE | G13: 106 | H13: 1998 | I13: 2001 | J13: =1+(I13-H13) -> 4 | K13: NÃO COBRE | L13: NÃO COBRE | M13: =IF(I13=0,0,$B$2-I13) -> 25 | N13: INATIVADO
A14: 024067-2 | B14: Peugeot | C14: 106 Selection 1.0 5p | D14: HATCH | E14: NÃO COBRE | F14: NÃO COBRE | G14: 106 | H14: 1998 | I14: 2001 | J14: =1+(I14-H14) -> 4 | K14: NÃO COBRE | L14: NÃO COBRE | M14: =IF(I14=0,0,$B$2-I14) -> 25 | N14: INATIVADO
A15: 024027-3 | B15: Peugeot | C15: 106 Soleil 1.0 3p | D15: HATCH | E15: NÃO COBRE | F15: NÃO COBRE | G15: 106 | H15: 1998 | I15: 2001 | J15: =1+(I15-H15) -> 4 | K15: NÃO COBRE | L15: NÃO COBRE | M15: =IF(I15=0,0,$B$2-I15) -> 25 | N15: INATIVADO
A16: 024068-0 | B16: Peugeot | C16: 106 Soleil 1.0 5p | D16: HATCH | E16: NÃO COBRE | F16: NÃO COBRE | G16: 106 | H16: 1998 | I16: 2001 | J16: =1+(I16-H16) -> 4 | K16: NÃO COBRE | L16: NÃO COBRE | M16: =IF(I16=0,0,$B$2-I16) -> 25 | N16: INATIVADO
A17: 024001-0 | B17: Peugeot | C17: 106 XN 3p e 5p | D17: HATCH | E17: NÃO COBRE | F17: NÃO COBRE | G17: 106 | H17: 1994 | I17: 1996 | J17: =1+(I17-H17) -> 3 | K17: NÃO COBRE | L17: NÃO COBRE | M17: =IF(I17=0,0,$B$2-I17) -> 30 | N17: INATIVADO
A18: 024002-8 | B18: Peugeot | C18: 106 XT | D18: HATCH | E18: NÃO COBRE | F18: NÃO COBRE | G18: 106 | H18: 1992 | I18: 1995 | J18: =1+(I18-H18) -> 4 | K18: NÃO COBRE | L18: NÃO COBRE | M18: =IF(I18=0,0,$B$2-I18) -> 31 | N18: INATIVADO
A19: 009171-5 | B19: BMW | C19: 116iA 1.6 TB 16V 136cv 5p | D19: HATCH | E19: NÃO COBRE | F19: NÃO COBRE | G19: Serie 1 | H19: 2012 | I19: 2015 | J19: =1+(I19-H19) -> 4 | K19: NÃO COBRE | L19: NÃO COBRE | M19: =IF(I19=0,0,$B$2-I19) -> 11
A20: 009298-3 | B20: BMW | C20: 118i M Sport 1.5 TB 12V Aut. 5p | E20: NÃO COBRE | F20: NÃO COBRE | G20: 118i | H20: 2023 | I20: 2026 | J20: =1+(I20-H20) -> 4 | K20: NÃO COBRE | L20: NÃO COBRE | M20: =IF(I20=0,0,$B$2-I20) -> 0
A21: 009258-4 | B21: BMW | C21: 118i Sport 1.5 TB 12V Aut. 5p | D21: HATCH | E21: NÃO COBRE | F21: NÃO COBRE | G21: Serie 1 | H21: 2020 | I21: 2022 | J21: =1+(I21-H21) -> 3 | K21: NÃO COBRE | L21: NÃO COBRE | M21: =IF(I21=0,0,$B$2-I21) -> 4
A22: 009152-9 | B22: BMW | C22: 118iA 2.0 16V 136cv 3p | D22: HATCH | E22: NÃO COBRE | F22: NÃO COBRE | G22: Serie 1 | H22: 2011 | I22: 2012 | J22: =1+(I22-H22) -> 2 | K22: NÃO COBRE | L22: NÃO COBRE | M22: =IF(I22=0,0,$B$2-I22) -> 14
A23: 009136-7 | B23: BMW | C23: 118iA 2.0 16V 136cv 5p | D23: HATCH | E23: NÃO COBRE | F23: NÃO COBRE | G23: Serie 1 | H23: 2010 | I23: 2012 | J23: =1+(I23-H23) -> 3 | K23: NÃO COBRE | L23: NÃO COBRE | M23: =IF(I23=0,0,$B$2-I23) -> 14
A24: 009169-3 | B24: BMW | C24: 118iA Full 1.6 TB 16V 170cv 5p | D24: HATCH | E24: NÃO COBRE | F24: NÃO COBRE | G24: Serie 1 | H24: 2012 | I24: 2014 | J24: =1+(I24-H24) -> 3 | K24: NÃO COBRE | L24: NÃO COBRE | M24: =IF(I24=0,0,$B$2-I24) -> 12
A25: 009159-6 | B25: BMW | C25: 118iA/ Urban/Sport 1.6 TB 16V 170cv 5p | D25: HATCH | E25: NÃO COBRE | F25: NÃO COBRE | G25: Serie 1 | H25: 2012 | I25: 2015 | J25: =1+(I25-H25) -> 4 | K25: NÃO COBRE | L25: NÃO COBRE | M25: =IF(I25=0,0,$B$2-I25) -> 11
A26: 009106-5 | B26: BMW | C26: 120i 2.0 16V 150cv/ 156cv 5p | D26: HATCH | E26: NÃO COBRE | F26: NÃO COBRE | G26: Serie 1 | H26: 2005 | I26: 2009 | J26: =1+(I26-H26) -> 5 | K26: NÃO COBRE | L26: NÃO COBRE | M26: =IF(I26=0,0,$B$2-I26) -> 17
A27: 009105-7 | B27: BMW | C27: 120iA 2.0 16V 150cv/ 156cv 5p | D27: HATCH | E27: NÃO COBRE | F27: NÃO COBRE | G27: Serie 1 | H27: 2005 | I27: 2012 | J27: =1+(I27-H27) -> 8 | K27: NÃO COBRE | L27: NÃO COBRE | M27: =IF(I27=0,0,$B$2-I27) -> 14
A28: 009129-4 | B28: BMW | C28: 120iA 2.0 16V 156cv 3p | D28: HATCH | E28: NÃO COBRE | F28: NÃO COBRE | G28: Serie 1 | H28: 2008 | I28: 2009 | J28: =1+(I28-H28) -> 2 | K28: NÃO COBRE | L28: NÃO COBRE | M28: =IF(I28=0,0,$B$2-I28) -> 17
A29: 009130-8 | B29: BMW | C29: 120iA Cabrio 2.0 16V 156cv 2p | D29: HATCH | E29: NÃO COBRE | F29: NÃO COBRE | G29: Serie 1 | H29: 2009 | I29: 2012 | J29: =1+(I29-H29) -> 4 | K29: NÃO COBRE | L29: NÃO COBRE | M29: =IF(I29=0,0,$B$2-I29) -> 14
A30: 009212-6 | B30: BMW | C30: 120iA Sport 2.0/ActiveFlex 16V Aut. | D30: HATCH | E30: NÃO COBRE | F30: NÃO COBRE | G30: Serie 1 | H30: 2015 | I30: 2019 | J30: =1+(I30-H30) -> 5 | K30: NÃO COBRE | L30: NÃO COBRE | M30: =IF(I30=0,0,$B$2-I30) -> 7
A31: 009176-6 | B31: BMW | C31: 125i M Sport/Active Flex 2.0 TB Aut. 5p | D31: HATCH | E31: NÃO COBRE | F31: NÃO COBRE | G31: Serie 1 | H31: 2013 | I31: 2019 | J31: =1+(I31-H31) -> 7 | K31: NÃO COBRE | L31: NÃO COBRE | M31: =IF(I31=0,0,$B$2-I31) -> 7
A32: 009109-0 | B32: BMW | C32: 130i 3.0 24V 265cv 5p | D32: HATCH | E32: NÃO COBRE | F32: NÃO COBRE | G32: Serie 1 | H32: 2006 | I32: 2009 | J32: =1+(I32-H32) -> 4 | K32: NÃO COBRE | L32: NÃO COBRE | M32: =IF(I32=0,0,$B$2-I32) -> 17
... A35: 009135-9 | B35: BMW | C35: 135iA Coupé 3.0 24V 306cv | D35: HATCH | E35: NÃO COBRE | F35: NÃO COBRE | G35: Serie 1 | H35: 2009 | I35: 2012 | J35: =1+(I35-H35) -> 4 | K35: NÃO COBRE | L35: NÃO COBRE | M35: =IF(I35=0,0,$B$2-I35) -> 14
A36: 001124-0 | B36: Fiat | C36: 147 C/ CL | D36: HATCH | E36: NÃO COBRE | F36: NÃO COBRE | G36: 147 | H36: 1985 | I36: 1985 | J36: =1+(I36-H36) -> 1 | K36: NÃO COBRE | L36: NÃO COBRE | M36: =IF(I36=0,0,$B$2-I36) -> 41 | N36: INATIVADO
A37: 001138-0 | B37: Fiat | C37: 147 Furgão (todos) | D37: UTILITÁRIOS | E37: NÃO COBRE | F37: NÃO COBRE | G37: 147 | H37: 1995 | I37: 1997 | J37: =1+(I37-H37) -> 3 | K37: NÃO COBRE | L37: NÃO COBRE | M37: =IF(I37=0,0,$B$2-I37) -> 29 | N37: INATIVADO
A38: 001123-1 | B38: Fiat | C38: 147 Pick-Up (todas) | D38: PICAPE | E38: NÃO COBRE | F38: NÃO COBRE | G38: 147 | H38: 1995 | I38: 1995 | J38: =1+(I38-H38) -> 1 | K38: NÃO COBRE | L38: NÃO COBRE | M38: =IF(I38=0,0,$B$2-I38) -> 31 | N38: INATIVADO
A39: 083024-0 | B39: RAM | C39: 1500 LARAM. NIGHT ED. BI-TB 3.0 4x4 Aut. | E39: #N/A | F39: #N/A | G39: 1500 | H39: 2025 | I39: 2026 | J39: =1+(I39-H39) -> 2 | K39: SOB CONSULTA | L39: SOB CONSULTA | M39: =IF(I39=0,0,$B$2-I39) -> 0
A40: 083025-9 | B40: RAM | C40: 1500 LARAMIE 3.0 CD BI-TB 4x4 Aut. | E40: #N/A | F40: #N/A | G40: 1500 | H40: 2025 | I40: 2026 | J40: =1+(I40-H40) -> 2 | K40: SOB CONSULTA | L40: SOB CONSULTA | M40: =IF(I40=0,0,$B$2-I40) -> 0
A41: 083014-3 | B41: RAM | C41: 1500 LIMITED 5.7 CD 4x4 Aut. | E41: #N/A | F41: #N/A | G41: 1500 | H41: 2022 | I41: 2024 | J41: =1+(I41-H41) -> 3 | K41: SOB CONSULTA | L41: SOB CONSULTA | M41: =IF(I41=0,0,$B$2-I41) -> 2
A42: 083013-5 | B42: RAM | C42: 1500 LIMITED NIGHT EDITION 5.7 4x4 Aut. | E42: #N/A | F42: #N/A | G42: 1500 | H42: 2023 | I42: 2024 | J42: =1+(I42-H42) -> 2 | K42: SOB CONSULTA | L42: SOB CONSULTA | M42: =IF(I42=0,0,$B$2-I42) -> 2
A43: 083004-6 | B43: RAM | C43: 1500 REBEL 5.7 HEMI CD V8 4x4 Aut. | E43: #N/A | F43: #N/A | G43: 1500 | H43: 2021 | I43: 2024 | J43: =1+(I43-H43) -> 4 | K43: SOB CONSULTA | L43: SOB CONSULTA | M43: =IF(I43=0,0,$B$2-I43) -> 2
A44: 021060-9 | B44: Mercedez-benz | C44: 180-D Pick-Up/Furgão 2.4 Diesel | D44: UTILITÁRIOS | E44: NÃO COBRE | F44: NÃO COBRE | G44: 180 | H44: 1993 | I44: 1996 | J44: =1+(I44-H44) -> 4 | K44: NÃO COBRE | L44: NÃO COBRE | M44: =IF(I44=0,0,$B$2-I44) -> 30
A45: 021061-7 | B45: Mercedez-benz | C45: 180-D Van 2.4 Diesel | D45: UTILITÁRIOS | E45: NÃO COBRE | F45: NÃO COBRE | G45: 180 | H45: 1993 | I45: 1996 | J45: =1+(I45-H45) -> 4 | K45: NÃO COBRE | L45: NÃO COBRE | M45: =IF(I45=0,0,$B$2-I45) -> 30
...

Sheet TAXA
A1: COTA DE PARTICIPAÇÃO | B1: TAXA | C1: VALOR MÍNIMO
A2: COTA 01 | B2: 5 | C2: 1250
A3: COTA 02 | B3: 6 | C3: 1500
A4: COTA 03 | B4: 7 | C4: 1750
A5: COTA 04 | B5: 8 | C5: 2000
A6: COTA 05 | B6: 9 | C6: 2250
A7: COTA 06 | B7: 10 | C7: 2500
A8: COTA 10 | B8: 15 | C8: 1250
A10: ZERO KM | B10: NOTA FISCAL DE COMPRA DE ATÉ 4 MESES | J10: FAIXA 01 | S10: FAIXA 02 | AB10: FAIXA 03 | AK10: FAIXA 04 | AT10: UBER/ LOCADORAS DIVERSAS | BC10: FROTA PARTICULAR OU LOCADORAS COM ANÁLISE DE PERFIL
A11: FIPE | B11: TAXA | C11: VALOR | D11: ASSIST | E11: 15 DIAS | F11: RASTREADOR | G11: MENSAL | H11: ANUAL | J11: FIPE | K11: TAXA | L11: VALOR | M11: ASSIST | N11: 15 DIAS | O11: RASTREADOR | P11: MENSAL | Q11: ANUAL | S11: FIPE | T11: TAXA | U11: VALOR | V11: ASSIST | W11: 15 DIAS | X11: RASTREADOR | Y11: MENSAL | Z11: ANUAL | AB11: FIPE | AC11: TAXA | AD11: VALOR | AE11: ASSIST | AF11: 15 DIAS | AG11: RASTREADOR | AH11: MENSAL | AI11: ANUAL | AK11: FIPE | AL11: TAXA | AM11: VALOR | AN11: ASSIST | AO11: 15 DIAS | AP11: RASTREADOR | AQ11: MENSAL | AR11: ANUAL | AT11: FIPE | AU11: TAXA | AV11: VALOR | AW11: ASSIST | AX11: 15 DIAS | AY11: RASTREADOR | AZ11: MENSAL | BA11: ANUAL | BC11: FIPE | BD11: TAXA | BE11: VALOR | BF11: ASSIST | BG11: 15 DIAS | BH11: RASTREADOR | BI11: MENSAL | BJ11: ANUAL
A12: =A13+10000 -> 195000 | B12: 0.0011 | C12: =B12*A12 -> 214.5 | D12: 18.9 | E12: 15.9 | F12: 0 | G12: =C12+D12+E12+F12 -> 249.3 | H12: =G12*12 -> 2991.6 | J12: =J13+10000 -> 195000 | K12: 0.0014 | L12: =K12*J12 -> 273 | M12: 18.9 | N12: 15.9 | O12: 0 | P12: =L12+M12+N12+O12 -> 307.8 | Q12: =P12*12 -> 3693.6 | S12: =S13+10000 -> 195000 | T12: 0.0016 | U12: =T12*S12 -> 312 | V12: 18.9 | W12: 15.9 | X12: 0 | Y12: =U12+V12+W12+X12 -> 346.8 | Z12: =Y12*12 -> 4161.6 | AB12: =AB13+10000 -> 195000 | AC12: 0.0019 | AD12: =AC12*AB12 -> 370.5 | AE12: 18.9 | AF12: 15.9 | AG12: 39.9 | AH12: =AD12+AE12+AF12+AG12 -> 445.2 | AI12: =AH12*12 -> 5342.4 | AK12: =AK13+10000 -> 195000 | AL12: =AL13-0.0001 -> 0.0036 | AM12: =AL12*AK12 -> 702 | AN12: 18.9 | AO12: 15.9 | AP12: 39.9 | AQ12: =AM12+AN12+AO12+AP12 -> 776.7 | AR12: =AQ12*12 -> 9320.4 | AT12: =AT13+10000 -> 195000 | AU12: 0.0019 | AV12: =AU12*AT12 -> 370.5 | AW12: 18.9 | AX12: 15.9 | AY12: 39.9 | AZ12: =AV12+AW12+AX12+AY12 -> 445.2 | BA12: =AZ12*12 -> 5342.4 | BC12: =BC13+10000 -> 195000 | BD12: 0.0019 | BE12: =BD12*BC12 -> 370.5 | BF12: 18.9 | BG12: 15.9 | BH12: 39.9 | BI12: =BE12+BF12+BG12+BH12 -> 445.2 | BJ12: =BI12*12 -> 5342.4
A13: =A14+10000 -> 185000 | B13: 0.0011 | C13: =B13*A13 -> 203.5 | D13: 18.9 | E13: 15.9 | F13: 0 | G13: =C13+D13+E13+F13 -> 238.3 | H13: =G13*12 -> 2859.6 | J13: =J14+10000 -> 185000 | K13: 0.0014 | L13: =K13*J13 -> 259 | M13: 18.9 | N13: 15.9 | O13: 0 | P13: =L13+M13+N13+O13 -> 293.8 | Q13: =P13*12 -> 3525.6 | S13: =S14+10000 -> 185000 | T13: 0.0016 | U13: =T13*S13 -> 296 | V13: 18.9 | W13: 15.9 | X13: 0 | Y13: =U13+V13+W13+X13 -> 330.8 | Z13: =Y13*12 -> 3969.6 | AB13: =AB14+10000 -> 185000 | AC13: 0.002 | AD13: =AC13*AB13 -> 370 | AE13: 18.9 | AF13: 15.9 | AG13: 39.9 | AH13: =AD13+AE13+AF13+AG13 -> 444.7 | AI13: =AH13*12 -> 5336.4 | AK13: =AK14+10000 -> 185000 | AL13: =AL14-0.0001 -> 0.0037 | AM13: =AL13*AK13 -> 684.5 | AN13: 18.9 | AO13: 15.9 | AP13: 39.9 | AQ13: =AM13+AN13+AO13+AP13 -> 759.2 | AR13: =AQ13*12 -> 9110.4 | AT13: =AT14+10000 -> 185000 | AU13: 0.002 | AV13: =AU13*AT13 -> 370 | AW13: 18.9 | AX13: 15.9 | AY13: 39.9 | AZ13: =AV13+AW13+AX13+AY13 -> 444.7 | BA13: =AZ13*12 -> 5336.4 | BC13: =BC14+10000 -> 185000 | BD13: 0.002 | BE13: =BD13*BC13 -> 370 | BF13: 18.9 | BG13: 15.9 | BH13: 39.9 | BI13: =BE13+BF13+BG13+BH13 -> 444.7 | BJ13: =BI13*12 -> 5336.4
A14: =A15+10000 -> 175000 | B14: 0.0011 | C14: =B14*A14 -> 192.5 | D14: 18.9 | E14: 15.9 | F14: 0 | G14: =C14+D14+E14+F14 -> 227.3 | H14: =G14*12 -> 2727.6 | J14: =J15+10000 -> 175000 | K14: 0.0014 | L14: =K14*J14 -> 245 | M14: 18.9 | N14: 15.9 | O14: 0 | P14: =L14+M14+N14+O14 -> 279.8 | Q14: =P14*12 -> 3357.6 | S14: =S15+10000 -> 175000 | T14: 0.0016 | U14: =T14*S14 -> 280 | V14: 18.9 | W14: 15.9 | X14: 0 | Y14: =U14+V14+W14+X14 -> 314.8 | Z14: =Y14*12 -> 3777.6 | AB14: =AB15+10000 -> 175000 | AC14: 0.0021 | AD14: =AC14*AB14 -> 367.5 | AE14: 18.9 | AF14: 15.9 | AG14: 39.9 | AH14: =AD14+AE14+AF14+AG14 -> 442.2 | AI14: =AH14*12 -> 5306.4 | AK14: =AK15+10000 -> 175000 | AL14: =AL15-0.0001 -> 0.0038 | AM14: =AL14*AK14 -> 665 | AN14: 18.9 | AO14: 15.9 | AP14: 39.9 | AQ14: =AM14+AN14+AO14+AP14 -> 739.7 | AR14: =AQ14*12 -> 8876.4 | AT14: =AT15+10000 -> 175000 | AU14: 0.0021 | AV14: =AU14*AT14 -> 367.5 | AW14: 18.9 | AX14: 15.9 | AY14: 39.9 | AZ14: =AV14+AW14+AX14+AY14 -> 442.2 | BA14: =AZ14*12 -> 5306.4 | BC14: =BC15+10000 -> 175000 | BD14: 0.0021 | BE14: =BD14*BC14 -> 367.5 | BF14: 18.9 | BG14: 15.9 | BH14: 39.9 | BI14: =BE14+BF14+BG14+BH14 -> 442.2 | BJ14: =BI14*12 -> 5306.4
A15: =A16+10000 -> 165000 | B15: 0.0012 | C15: =B15*A15 -> 198 | D15: 18.9 | E15: 15.9 | F15: 0 | G15: =C15+D15+E15+F15 -> 232.8 | H15: =G15*12 -> 2793.6 | J15: =J16+10000 -> 165000 | K15: 0.0014 | L15: =K15*J15 -> 231 | M15: 18.9 | N15: 15.9 | O15: 0 | P15: =L15+M15+N15+O15 -> 265.8 | Q15: =P15*12 -> 3189.6 | S15: =S16+10000 -> 165000 | T15: 0.0016 | U15: =T15*S15 -> 264 | V15: 18.9 | W15: 15.9 | X15: 0 | Y15: =U15+V15+W15+X15 -> 298.8 | Z15: =Y15*12 -> 3585.6 | AB15: =AB16+10000 -> 165000 | AC15: 0.0022 | AD15: =AC15*AB15 -> 363 | AE15: 18.9 | AF15: 15.9 | AG15: 39.9 | AH15: =AD15+AE15+AF15+AG15 -> 437.7 | AI15: =AH15*12 -> 5252.4 | AK15: =AK16+10000 -> 165000 | AL15: =AL16-0.0001 -> 0.0039 | AM15: =AL15*AK15 -> 643.5 | AN15: 18.9 | AO15: 15.9 | AP15: 39.9 | AQ15: =AM15+AN15+AO15+AP15 -> 718.2 | AR15: =AQ15*12 -> 8618.4 | AT15: =AT16+10000 -> 165000 | AU15: 0.0022 | AV15: =AU15*AT15 -> 363 | AW15: 18.9 | AX15: 15.9 | AY15: 39.9 | AZ15: =AV15+AW15+AX15+AY15 -> 437.7 | BA15: =AZ15*12 -> 5252.4 | BC15: =BC16+10000 -> 165000 | BD15: 0.0022 | BE15: =BD15*BC15 -> 363 | BF15: 18.9 | BG15: 15.9 | BH15: 39.9 | BI15: =BE15+BF15+BG15+BH15 -> 437.7 | BJ15: =BI15*12 -> 5252.4
A16: =A17+10000 -> 155000 | B16: 0.0012 | C16: =B16*A16 -> 186 | D16: 18.9 | E16: 15.9 | F16: 0 | G16: =C16+D16+E16+F16 -> 220.8 | H16: =G16*12 -> 2649.6 | J16: =J17+10000 -> 155000 | K16: 0.0014 | L16: =K16*J16 -> 217 | M16: 18.9 | N16: 15.9 | O16: 0 | P16: =L16+M16+N16+O16 -> 251.8 | Q16: =P16*12 -> 3021.6 | S16: =S17+10000 -> 155000 | T16: 0.0016 | U16: =T16*S16 -> 248 | V16: 18.9 | W16: 15.9 | X16: 0 | Y16: =U16+V16+W16+X16 -> 282.8 | Z16: =Y16*12 -> 3393.6 | AB16: =AB17+10000 -> 155000 | AC16: 0.0023 | AD16: =AC16*AB16 -> 356.5 | AE16: 18.9 | AF16: 15.9 | AG16: 39.9 | AH16: =AD16+AE16+AF16+AG16 -> 431.2 | AI16: =AH16*12 -> 5174.4 | AK16: =AK17+10000 -> 155000 | AL16: 0.004 | AM16: =AL16*AK16 -> 620 | AN16: 18.9 | AO16: 15.9 | AP16: 39.9 | AQ16: =AM16+AN16+AO16+AP16 -> 694.7 | AR16: =AQ16*12 -> 8336.4 | AT16: =AT17+10000 -> 155000 | AU16: 0.0023 | AV16: =AU16*AT16 -> 356.5 | AW16: 18.9 | AX16: 15.9 | AY16: 39.9 | AZ16: =AV16+AW16+AX16+AY16 -> 431.2 | BA16: =AZ16*12 -> 5174.4 | BC16: =BC17+10000 -> 155000 | BD16: 0.0023 | BE16: =BD16*BC16 -> 356.5 | BF16: 18.9 | BG16: 15.9 | BH16: 39.9 | BI16: =BE16+BF16+BG16+BH16 -> 431.2 | BJ16: =BI16*12 -> 5174.4
A17: =A18+10000 -> 145000 | B17: 0.0013 | C17: =B17*A17 -> 188.5 | D17: 18.9 | E17: 15.9 | F17: 0 | G17: =C17+D17+E17+F17 -> 223.3 | H17: =G17*12 -> 2679.6 | J17: =J18+10000 -> 145000 | K17: 0.0016 | L17: =K17*J17 -> 232 | M17: 18.9 | N17: 15.9 | O17: 0 | P17: =L17+M17+N17+O17 -> 266.8 | Q17: =P17*12 -> 3201.6 | S17: =S18+10000 -> 145000 | T17: 0.0016 | U17: =T17*S17 -> 232 | V17: 18.9 | W17: 15.9 | X17: 39.9 | Y17: =U17+V17+W17+X17 -> 306.7 | Z17: =Y17*12 -> 3680.4 | AB17: =AB18+10000 -> 145000 | AC17: 0.0024 | AD17: =AC17*AB17 -> 348 | AE17: 18.9 | AF17: 15.9 | AG17: 39.9 | AH17: =AD17+AE17+AF17+AG17 -> 422.7 | AI17: =AH17*12 -> 5072.4 | AK17: =AK18+10000 -> 145000 | AL17: =AL18-0.0001 -> 0.0046 | AM17: =AL17*AK17 -> 667 | AN17: 18.9 | AO17: 15.9 | AP17: 39.9 | AQ17: =AM17+AN17+AO17+AP17 -> 741.7 | AR17: =AQ17*12 -> 8900.4 | AT17: =AT18+10000 -> 145000 | AU17: 0.0024 | AV17: =AU17*AT17 -> 348 | AW17: 18.9 | AX17: 15.9 | AY17: 39.9 | AZ17: =AV17+AW17+AX17+AY17 -> 422.7 | BA17: =AZ17*12 -> 5072.4 | BC17: =BC18+10000 -> 145000 | BD17: 0.0024 | BE17: =BD17*BC17 -> 348 | BF17: 18.9 | BG17: 15.9 | BH17: 39.9 | BI17: =BE17+BF17+BG17+BH17 -> 422.7 | BJ17: =BI17*12 -> 5072.4
A18: =A19+10000 -> 135000 | B18: 0.0014 | C18: =B18*A18 -> 189 | D18: 18.9 | E18: 15.9 | F18: 0 | G18: =C18+D18+E18+F18 -> 223.8 | H18: =G18*12 -> 2685.6 | J18: =J19+10000 -> 135000 | K18: 0.0016 | L18: =K18*J18 -> 216 | M18: 18.9 | N18: 15.9 | O18: 0 | P18: =L18+M18+N18+O18 -> 250.8 | Q18: =P18*12 -> 3009.6 | S18: =S19+10000 -> 135000 | T18: 0.0016 | U18: =T18*S18 -> 216 | V18: 18.9 | W18: 15.9 | X18: 39.9 | Y18: =U18+V18+W18+X18 -> 290.7 | Z18: =Y18*12 -> 3488.4 | AB18: =AB19+10000 -> 135000 | AC18: 0.0025 | AD18: =AC18*AB18 -> 337.5 | AE18: 18.9 | AF18: 15.9 | AG18: 39.9 | AH18: =AD18+AE18+AF18+AG18 -> 412.2 | AI18: =AH18*12 -> 4946.4 | AK18: =AK19+10000 -> 135000 | AL18: =AL19-0.0001 -> 0.0047 | AM18: =AL18*AK18 -> 634.5 | AN18: 18.9 | AO18: 15.9 | AP18: 39.9 | AQ18: =AM18+AN18+AO18+AP18 -> 709.2 | AR18: =AQ18*12 -> 8510.4 | AT18: =AT19+10000 -> 135000 | AU18: 0.0025 | AV18: =AU18*AT18 -> 337.5 | AW18: 18.9 | AX18: 15.9 | AY18: 39.9 | AZ18: =AV18+AW18+AX18+AY18 -> 412.2 | BA18: =AZ18*12 -> 4946.4 | BC18: =BC19+10000 -> 135000 | BD18: 0.0025 | BE18: =BD18*BC18 -> 337.5 | BF18: 18.9 | BG18: 15.9 | BH18: 39.9 | BI18: =BE18+BF18+BG18+BH18 -> 412.2 | BJ18: =BI18*12 -> 4946.4
A19: =A20+10000 -> 125000 | B19: 0.0015 | C19: =B19*A19 -> 187.5 | D19: 18.9 | E19: 15.9 | F19: 0 | G19: =C19+D19+E19+F19 -> 222.3 | H19: =G19*12 -> 2667.6 | J19: =J20+10000 -> 125000 | K19: 0.0016 | L19: =K19*J19 -> 200 | M19: 18.9 | N19: 15.9 | O19: 0 | P19: =L19+M19+N19+O19 -> 234.8 | Q19: =P19*12 -> 2817.6 | S19: =S20+10000 -> 125000 | T19: 0.0016 | U19: =T19*S19 -> 200 | V19: 18.9 | W19: 15.9 | X19: 39.9 | Y19: =U19+V19+W19+X19 -> 274.7 | Z19: =Y19*12 -> 3296.4 | AB19: =AB20+10000 -> 125000 | AC19: 0.0026 | AD19: =AC19*AB19 -> 325 | AE19: 18.9 | AF19: 15.9 | AG19: 39.9 | AH19: =AD19+AE19+AF19+AG19 -> 399.7 | AI19: =AH19*12 -> 4796.4 | AK19: =AK20+10000 -> 125000 | AL19: =AL20-0.0001 -> 0.0048 | AM19: =AL19*AK19 -> 600 | AN19: 18.9 | AO19: 15.9 | AP19: 39.9 | AQ19: =AM19+AN19+AO19+AP19 -> 674.7 | AR19: =AQ19*12 -> 8096.4 | AT19: =AT20+10000 -> 125000 | AU19: 0.0026 | AV19: =AU19*AT19 -> 325 | AW19: 18.9 | AX19: 15.9 | AY19: 39.9 | AZ19: =AV19+AW19+AX19+AY19 -> 399.7 | BA19: =AZ19*12 -> 4796.4 | BC19: =BC20+10000 -> 125000 | BD19: 0.0026 | BE19: =BD19*BC19 -> 325 | BF19: 18.9 | BG19: 15.9 | BH19: 39.9 | BI19: =BE19+BF19+BG19+BH19 -> 399.7 | BJ19: =BI19*12 -> 4796.4
A20: =A21+10000 -> 115000 | B20: 0.0015 | C20: =B20*A20 -> 172.5 | D20: 18.9 | E20: 15.9 | F20: 0 | G20: =C20+D20+E20+F20 -> 207.3 | H20: =G20*12 -> 2487.6 | J20: =J21+10000 -> 115000 | K20: 0.0016 | L20: =K20*J20 -> 184 | M20: 18.9 | N20: 15.9 | O20: 0 | P20: =L20+M20+N20+O20 -> 218.8 | Q20: =P20*12 -> 2625.6 | S20: =S21+10000 -> 115000 | T20: 0.0016 | U20: =T20*S20 -> 184 | V20: 18.9 | W20: 15.9 | X20: 39.9 | Y20: =U20+V20+W20+X20 -> 258.7 | Z20: =Y20*12 -> 3104.4 | AB20: =AB21+10000 -> 115000 | AC20: 0.0027 | AD20: =AC20*AB20 -> 310.5 | AE20: 18.9 | AF20: 15.9 | AG20: 39.9 | AH20: =AD20+AE20+AF20+AG20 -> 385.2 | AI20: =AH20*12 -> 4622.4 | AK20: =AK21+10000 -> 115000 | AL20: =AL21-0.0001 -> 0.0049 | AM20: =AL20*AK20 -> 563.5 | AN20: 18.9 | AO20: 15.9 | AP20: 39.9 | AQ20: =AM20+AN20+AO20+AP20 -> 638.2 | AR20: =AQ20*12 -> 7658.4 | AT20: =AT21+10000 -> 115000 | AU20: 0.0027 | AV20: =AU20*AT20 -> 310.5 | AW20: 18.9 | AX20: 15.9 | AY20: 39.9 | AZ20: =AV20+AW20+AX20+AY20 -> 385.2 | BA20: =AZ20*12 -> 4622.4 | BC20: =BC21+10000 -> 115000 | BD20: 0.0027 | BE20: =BD20*BC20 -> 310.5 | BF20: 18.9 | BG20: 15.9 | BH20: 39.9 | BI20: =BE20+BF20+BG20+BH20 -> 385.2 | BJ20: =BI20*12 -> 4622.4
A21: =A22+10000 -> 105000 | B21: 0.0016 | C21: =B21*A21 -> 168 | D21: 18.9 | E21: 15.9 | F21: 0 | G21: =C21+D21+E21+F21 -> 202.8 | H21: =G21*12 -> 2433.6 | J21: =J22+10000 -> 105000 | K21: 0.0016 | L21: =K21*J21 -> 168 | M21: 18.9 | N21: 15.9 | O21: 0 | P21: =L21+M21+N21+O21 -> 202.8 | Q21: =P21*12 -> 2433.6 | S21: =S22+10000 -> 105000 | T21: 0.0016 | U21: =T21*S21 -> 168 | V21: 18.9 | W21: 15.9 | X21: 39.9 | Y21: =U21+V21+W21+X21 -> 242.7 | Z21: =Y21*12 -> 2912.4 | AB21: =AB22+10000 -> 105000 | AC21: 0.0028 | AD21: =AC21*AB21 -> 294 | AE21: 18.9 | AF21: 15.9 | AG21: 39.9 | AH21: =AD21+AE21+AF21+AG21 -> 368.7 | AI21: =AH21*12 -> 4424.4 | AK21: =AK22+10000 -> 105000 | AL21: 0.005 | AM21: =AL21*AK21 -> 525 | AN21: 18.9 | AO21: 15.9 | AP21: 39.9 | AQ21: =AM21+AN21+AO21+AP21 -> 599.7 | AR21: =AQ21*12 -> 7196.4 | AT21: =AT22+10000 -> 105000 | AU21: 0.0028 | AV21: =AU21*AT21 -> 294 | AW21: 18.9 | AX21: 15.9 | AY21: 39.9 | AZ21: =AV21+AW21+AX21+AY21 -> 368.7 | BA21: =AZ21*12 -> 4424.4 | BC21: =BC22+10000 -> 105000 | BD21: 0.0028 | BE21: =BD21*BC21 -> 294 | BF21: 18.9 | BG21: 15.9 | BH21: 39.9 | BI21: =BE21+BF21+BG21+BH21 -> 368.7 | BJ21: =BI21*12 -> 4424.4
A22: =A23+10000 -> 95000 | B22: =B23-0.0001 -> 0.0017 | C22: =B22*A22 -> 161.5 | D22: 18.9 | E22: 15.9 | F22: 0 | G22: =C22+D22+E22+F22 -> 196.3 | H22: =G22*12 -> 2355.6 | J22: =J23+10000 -> 95000 | K22: 0.0017 | L22: =K22*J22 -> 161.5 | M22: 18.9 | N22: 15.9 | O22: 0 | P22: =L22+M22+N22+O22 -> 196.3 | Q22: =P22*12 -> 2355.6 | S22: =S23+10000 -> 95000 | T22: 0.0016 | U22: =T22*S22 -> 152 | V22: 18.9 | W22: 15.9 | X22: 39.9 | Y22: =U22+V22+W22+X22 -> 226.7 | Z22: =Y22*12 -> 2720.4 | AB22: =AB23+10000 -> 95000 | AC22: 0.0029 | AD22: =AC22*AB22 -> 275.5 | AE22: 18.9 | AF22: 15.9 | AG22: 39.9 | AH22: =AD22+AE22+AF22+AG22 -> 350.2 | AI22: =AH22*12 -> 4202.4 | AK22: =AK23+10000 -> 95000 | AL22: =AL23-0.0001 -> 0.0053 | AM22: =AL22*AK22 -> 503.5 | AN22: 18.9 | AO22: 15.9 | AP22: 39.9 | AQ22: =AM22+AN22+AO22+AP22 -> 578.2 | AR22: =AQ22*12 -> 6938.4 | AT22: =AT23+10000 -> 95000 | AU22: 0.0029 | AV22: =AU22*AT22 -> 275.5 | AW22: 18.9 | AX22: 15.9 | AY22: 39.9 | AZ22: =AV22+AW22+AX22+AY22 -> 350.2 | BA22: =AZ22*12 -> 4202.4 | BC22: =BC23+10000 -> 95000 | BD22: 0.0029 | BE22: =BD22*BC22 -> 275.5 | BF22: 18.9 | BG22: 15.9 | BH22: 39.9 | BI22: =BE22+BF22+BG22+BH22 -> 350.2 | BJ22: =BI22*12 -> 4202.4
A23: =A24+10000 -> 85000 | B23: 0.0018 | C23: =B23*A23 -> 153 | D23: 18.9 | E23: 15.9 | F23: 0 | G23: =C23+D23+E23+F23 -> 187.8 | H23: =G23*12 -> 2253.6 | J23: =J24+10000 -> 85000 | K23: 0.0018 | L23: =K23*J23 -> 153 | M23: 18.9 | N23: 15.9 | O23: 0 | P23: =L23+M23+N23+O23 -> 187.8 | Q23: =P23*12 -> 2253.6 | S23: =S24+10000 -> 85000 | T23: 0.0017 | U23: =T23*S23 -> 144.5 | V23: 18.9 | W23: 15.9 | X23: 39.9 | Y23: =U23+V23+W23+X23 -> 219.2 | Z23: =Y23*12 -> 2630.4 | AB23: =AB24+10000 -> 85000 | AC23: 0.003 | AD23: =AC23*AB23 -> 255 | AE23: 18.9 | AF23: 15.9 | AG23: 39.9 | AH23: =AD23+AE23+AF23+AG23 -> 329.7 | AI23: =AH23*12 -> 3956.4 | AK23: =AK24+10000 -> 85000 | AL23: =AL24-0.0001 -> 0.0054 | AM23: =AL23*AK23 -> 459 | AN23: 18.9 | AO23: 15.9 | AP23: 39.9 | AQ23: =AM23+AN23+AO23+AP23 -> 533.7 | AR23: =AQ23*12 -> 6404.4 | AT23: =AT24+10000 -> 85000 | AU23: 0.003 | AV23: =AU23*AT23 -> 255 | AW23: 18.9 | AX23: 15.9 | AY23: 39.9 | AZ23: =AV23+AW23+AX23+AY23 -> 329.7 | BA23: =AZ23*12 -> 3956.4 | BC23: =BC24+10000 -> 85000 | BD23: 0.003 | BE23: =BD23*BC23 -> 255 | BF23: 18.9 | BG23: 15.9 | BH23: 39.9 | BI23: =BE23+BF23+BG23+BH23 -> 329.7 | BJ23: =BI23*12 -> 3956.4
A24: 75000 | B24: 0.0018 | C24: =B24*A24 -> 135 | D24: 18.9 | E24: 15.9 | F24: 0 | G24: =C24+D24+E24+F24 -> 169.8 | H24: =G24*12 -> 2037.6 | J24: =J25+10000 -> 75000 | K24: 0.0019 | L24: =K24*J24 -> 142.5 | M24: 18.9 | N24: 15.9 | O24: 0 | P24: =L24+M24+N24+O24 -> 177.3 | Q24: =P24*12 -> 2127.6 | S24: =S25+10000 -> 75000 | T24: 0.0018 | U24: =T24*S24 -> 135 | V24: 18.9 | W24: 15.9 | X24: 39.9 | Y24: =U24+V24+W24+X24 -> 209.7 | Z24: =Y24*12 -> 2516.4 | AB24: =AB25+10000 -> 75000 | AC24: 0.0035 | AD24: =AC24*AB24 -> 262.5 | AE24: 18.9 | AF24: 15.9 | AG24: 39.9 | AH24: =AD24+AE24+AF24+AG24 -> 337.2 | AI24: =AH24*12 -> 4046.4 | AK24: =AK25+10000 -> 75000 | AL24: =AL25-0.0001 -> 0.0055 | AM24: =AL24*AK24 -> 412.5 | AN24: 18.9 | AO24: 15.9 | AP24: 39.9 | AQ24: =AM24+AN24+AO24+AP24 -> 487.2 | AR24: =AQ24*12 -> 5846.4 | AT24: =AT25+10000 -> 75000 | AU24: 0.0039 | AV24: =AU24*AT24 -> 292.5 | AW24: 18.9 | AX24: 15.9 | AY24: 39.9 | AZ24: =AV24+AW24+AX24+AY24 -> 367.2 | BA24: =AZ24*12 -> 4406.4 | BC24: =BC25+10000 -> 75000 | BD24: 0.0033 | BE24: =BD24*BC24 -> 247.5 | BF24: 18.9 | BG24: 15.9 | BH24: 39.9 | BI24: =BE24+BF24+BG24+BH24 -> 322.2 | BJ24: =BI24*12 -> 3866.4
J25: =J26+10000 -> 65000 | K25: 0.002 | L25: =K25*J25 -> 130 | M25: 18.9 | N25: 15.9 | O25: 0 | P25: =L25+M25+N25+O25 -> 164.8 | Q25: =P25*12 -> 1977.6 | S25: =S26+10000 -> 65000 | T25: 0.0032 | U25: =T25*S25 -> 208 | V25: 18.9 | W25: 15.9 | X25: 0 | Y25: =U25+V25+W25+X25 -> 242.8 | Z25: =Y25*12 -> 2913.6 | AB25: =AB26+10000 -> 65000 | AC25: 0.0036 | AD25: =AC25*AB25 -> 234 | AE25: 18.9 | AF25: 15.9 | AG25: 39.9 | AH25: =AD25+AE25+AF25+AG25 -> 308.7 | AI25: =AH25*12 -> 3704.4 | AK25: =AK26+10000 -> 65000 | AL25: =AL26-0.0001 -> 0.0056 | AM25: =AL25*AK25 -> 364 | AN25: 18.9 | AO25: 15.9 | AP25: 39.9 | AQ25: =AM25+AN25+AO25+AP25 -> 438.7 | AR25: =AQ25*12 -> 5264.4 | AT25: =AT26+10000 -> 65000 | AU25: 0.004 | AV25: =AU25*AT25 -> 260 | AW25: 18.9 | AX25: 15.9 | AY25: 39.9 | AZ25: =AV25+AW25+AX25+AY25 -> 334.7 | BA25: =AZ25*12 -> 4016.4 | BC25: =BC26+10000 -> 65000 | BD25: 0.0034 | BE25: =BD25*BC25 -> 221 | BF25: 18.9 | BG25: 15.9 | BH25: 39.9 | BI25: =BE25+BF25+BG25+BH25 -> 295.7 | BJ25: =BI25*12 -> 3548.4
J26: =J27+10000 -> 55000 | K26: 0.0022 | L26: =K26*J26 -> 121 | M26: 18.9 | N26: 15.9 | O26: 0 | P26: =L26+M26+N26+O26 -> 155.8 | Q26: =P26*12 -> 1869.6 | S26: =S27+10000 -> 55000 | T26: 0.0033 | U26: =T26*S26 -> 181.5 | V26: 18.9 | W26: 15.9 | X26: 0 | Y26: =U26+V26+W26+X26 -> 216.3 | Z26: =Y26*12 -> 2595.6 | AB26: =AB27+10000 -> 55000 | AC26: 0.0037 | AD26: =AC26*AB26 -> 203.5 | AE26: 18.9 | AF26: 15.9 | AG26: 39.9 | AH26: =AD26+AE26+AF26+AG26 -> 278.2 | AI26: =AH26*12 -> 3338.4 | AK26: =AK27+10000 -> 55000 | AL26: =AL27-0.0001 -> 0.0057 | AM26: =AL26*AK26 -> 313.5 | AN26: 18.9 | AO26: 15.9 | AP26: 39.9 | AQ26: =AM26+AN26+AO26+AP26 -> 388.2 | AR26: =AQ26*12 -> 4658.4 | AT26: =AT27+10000 -> 55000 | AU26: 0.0041 | AV26: =AU26*AT26 -> 225.5 | AW26: 18.9 | AX26: 15.9 | AY26: 39.9 | AZ26: =AV26+AW26+AX26+AY26 -> 300.2 | BA26: =AZ26*12 -> 3602.4 | BC26: =BC27+10000 -> 55000 | BD26: 0.0035 | BE26: =BD26*BC26 -> 192.5 | BF26: 18.9 | BG26: 15.9 | BH26: 39.9 | BI26: =BE26+BF26+BG26+BH26 -> 267.2 | BJ26: =BI26*12 -> 3206.4
J27: =J28+10000 -> 45000 | K27: 0.0025 | L27: =K27*J27 -> 112.5 | M27: 18.9 | N27: 15.9 | O27: 0 | P27: =L27+M27+N27+O27 -> 147.3 | Q27: =P27*12 -> 1767.6 | S27: =S28+10000 -> 45000 | T27: 0.0035 | U27: =T27*S27 -> 157.5 | V27: 18.9 | W27: 15.9 | X27: 0 | Y27: =U27+V27+W27+X27 -> 192.3 | Z27: =Y27*12 -> 2307.6 | AB27: =AB28+10000 -> 45000 | AC27: 0.0038 | AD27: =AC27*AB27 -> 171 | AE27: 18.9 | AF27: 15.9 | AG27: 39.9 | AH27: =AD27+AE27+AF27+AG27 -> 245.7 | AI27: =AH27*12 -> 2948.4 | AK27: =AK28+10000 -> 45000 | AL27: =AL28-0.0001 -> 0.0058 | AM27: =AL27*AK27 -> 261 | AN27: 18.9 | AO27: 15.9 | AP27: 39.9 | AQ27: =AM27+AN27+AO27+AP27 -> 335.7 | AR27: =AQ27*12 -> 4028.4 | AT27: =AT28+10000 -> 45000 | AU27: 0.0042 | AV27: =AU27*AT27 -> 189 | AW27: 18.9 | AX27: 15.9 | AY27: 39.9 | AZ27: =AV27+AW27+AX27+AY27 -> 263.7 | BA27: =AZ27*12 -> 3164.4 | BC27: =BC28+10000 -> 45000 | BD27: 0.0036 | BE27: =BD27*BC27 -> 162 | BF27: 18.9 | BG27: 15.9 | BH27: 39.9 | BI27: =BE27+BF27+BG27+BH27 -> 236.7 | BJ27: =BI27*12 -> 2840.4
J28: =J29+10000 -> 35000 | K28: 0.0028 | L28: =K28*J28 -> 98 | M28: 18.9 | N28: 15.9 | O28: 0 | P28: =L28+M28+N28+O28 -> 132.8 | Q28: =P28*12 -> 1593.6 | S28: =S29+10000 -> 35000 | T28: 0.0036 | U28: =T28*S28 -> 126 | V28: 18.9 | W28: 15.9 | X28: 0 | Y28: =U28+V28+W28+X28 -> 160.8 | Z28: =Y28*12 -> 1929.6 | AB28: =AB29+10000 -> 35000 | AC28: 0.0039 | AD28: =AC28*AB28 -> 136.5 | AE28: 18.9 | AF28: 15.9 | AG28: 39.9 | AH28: =AD28+AE28+AF28+AG28 -> 211.2 | AI28: =AH28*12 -> 2534.4 | AK28: =AK29+10000 -> 35000 | AL28: =AL29-0.0001 -> 0.0059 | AM28: =AL28*AK28 -> 206.5 | AN28: 18.9 | AO28: 15.9 | AP28: 39.9 | AQ28: =AM28+AN28+AO28+AP28 -> 281.2 | AR28: =AQ28*12 -> 3374.4 | AT28: =AT29+10000 -> 35000 | AU28: 0.0043 | AV28: =AU28*AT28 -> 150.5 | AW28: 18.9 | AX28: 15.9 | AY28: 39.9 | AZ28: =AV28+AW28+AX28+AY28 -> 225.2 | BA28: =AZ28*12 -> 2702.4 | BC28: =BC29+10000 -> 35000 | BD28: 0.0037 | BE28: =BD28*BC28 -> 129.5 | BF28: 18.9 | BG28: 15.9 | BH28: 39.9 | BI28: =BE28+BF28+BG28+BH28 -> 204.2 | BJ28: =BI28*12 -> 2450.4
J29: 25000 | K29: 0.003 | L29: =K29*J29 -> 75 | M29: 18.9 | N29: 15.9 | O29: 0 | P29: =L29+M29+N29+O29 -> 109.8 | Q29: =P29*12 -> 1317.6 | S29: 25000 | T29: 0.0038 | U29: =T29*S29 -> 95 | V29: 18.9 | W29: 15.9 | X29: 0 | Y29: =U29+V29+W29+X29 -> 129.8 | Z29: =Y29*12 -> 1557.6 | AB29: 25000 | AC29: 0.004 | AD29: =AC29*AB29 -> 100 | AE29: 18.9 | AF29: 15.9 | AG29: 39.9 | AH29: =AD29+AE29+AF29+AG29 -> 174.7 | AI29: =AH29*12 -> 2096.4 | AK29: 25000 | AL29: 0.006 | AM29: =AL29*AK29 -> 150 | AN29: 18.9 | AO29: 15.9 | AP29: 39.9 | AQ29: =AM29+AN29+AO29+AP29 -> 224.7 | AR29: =AQ29*12 -> 2696.4 | AT29: 25000 | AU29: 0.0044 | AV29: =AU29*AT29 -> 110 | AW29: 18.9 | AX29: 15.9 | AY29: 39.9 | AZ29: =AV29+AW29+AX29+AY29 -> 184.7 | BA29: =AZ29*12 -> 2216.4 | BC29: 25000 | BD29: 0.0038 | BE29: =BD29*BC29 -> 95 | BF29: 18.9 | BG29: 15.9 | BH29: 39.9 | BI29: =BE29+BF29+BG29+BH29 -> 169.7 | BJ29: =BI29*12 -> 2036.4
